Workbook

Sheet Sociedades
A1: Sociedad | B1: País
A2: TRAN | B2: Colombia
A3: ISA | B3: Colombia
A4: ITCH | B4: Chile
A5: CEYA
A6: CABA | B6: Colombia
A7: RPAE
A8: CTMP | B8: Perú
A9: REPD | B9: Perú
A10: ISAP | B10: Perú

Sheet Clase
A1: Sociedad | B1: Clase | C1: Descripción Clase
A2: ITCH | B2: 3A050200 | C2: Terrenos Rurales
A3: ITCH | B3: 3A400100 | C3: Edificios
A4: ITCH | B4: 3A400201 | C4: Leasing Financiero - Edificaciones
A5: ITCH | B5: 3A400202 | C5: Leasing Financiero - Edificaciones Relacion
A6: ITCH | B6: 3A451210 | C6: Equipos de Subestación Nueva Estruc 40 Años
A7: ITCH | B7: 3A451211 | C7: Equipos de Subestación Nueva Estruc 38 Años
A8: ITCH | B8: 3A451212 | C8: Equipos de Subestación Nueva Estruc 32 Años
A9: ITCH | B9: 3A451213 | C9: Equipos de Subestación Nueva Estruc 30 Años
A10: ITCH | B10: 3A451214 | C10: Equipos de Subestación Nueva Estruc 27 Años
A11: ITCH | B11: 3A451215 | C11: Equipos de Subestación Nueva Estruc 25 Años
A12: ITCH | B12: 3A451216 | C12: Equipos de Subestación Nueva Estruc 20 Años
... A292: CABA | B292: RC900210 | C292: Seguro - Seguros proyectos

Sheet Criterio 
A1: Sociedad | B1: Criterio 1 | C1: Asignación Criterio de Clasificación 1 | D1: Criterio 2 | E1: Asignación Criterio de Clasificación 2 | F1: Criterio 3 | G1: Asignación Criterio de Clasificación 3 | H1: Criterio 4 | I1: Asignación Criterio de Clasificación 4 | J1: Criterio 5 | K1: Asignación Criterio de Clasificación 5
A2: ITCH | F2: IC01 | G2: LT 2X500 KV Carrdones-Polpaico | J2: ICA10000 | K2: ACTIVOS ADMIN CORP
A3: ITCH | F3: IC02 | G3: Nueva Linea encuentro lagunas | J3: ICO10000 | K3: ACTIVOS ADMIN OYM
A4: ITCH | F4: IC03 | G4: Obra de ampliación tendido seg | J4: ICO20000 | K4: ACTIVOS EN ALMACEN
A5: ITCH | F5: IC04 | G5: Banco de autotransformadores D | J5: P001L001 | K5: Cardones-Maitencillo500kV-Conexiones220k
A6: ITCH | F6: IC05 | G6: Ampliación barras 500 kv SE NU | J6: P001L002 | K6: Maitencillo-PanDeAzucar500kV-Conexiones2
A7: ITCH | F7: IC06 | G7: Diagonal 3 y 4 220kv NMAI NPAN | J7: P001L003 | K7: PanDeAzucar-Polpaico500kV-Conexiones220k
A8: ITCH | F8: IC07 | G8: Bco autotransormador N1 DS373 | J8: P001S001 | K8: SE Nueva Cardones 500/220kV
A9: ITCH | F9: IC08 | G9: CS POLP Y STATCOM NPAN 500kv | J9: P001S002 | K9: AmpliaciónSECardonesExistente220kV
A10: ITCH | F10: IC09 | G10: Mando sincronizado atr ncar | J10: P001S003 | K10: SE Nueva Maitencillo 500/220kV
A11: ITCH | F11: IC11 | G11: Aumento Capacidad LT220 kV MAI- NMAI | J11: P001S004 | K11: AmpliaciónSEMaitencilloExistente220kV
A12: ITCH | F12: IC12 | G12: Ampliación Subestación NPAZ | J12: P001S005 | K12: SE Nueva Pan de Azúcar 500/220 kV
A13: ITCH | F13: ICA1 | G13: ACTIVOS ADMIN CORP | J13: P001S006 | K13: AmpliaciónSEPanDeAzucarExistente220kV
... A15: ITCH | F15: ICO2 | G15: ACTIVOS EN ALMACEN | J15: P002L004 | K15: Encuentro-Lagunas 2X220 kV 1Circuito
A16: ITCH | J16: P002S008 | K16: AmpliacionSE_LagunasExistente220kV
A17: ITCH | J17: P002S009 | K17: AmpliacionSE_EncuentroExistente220kV
A18: ITCH | J18: P003L004 | K18: 2do C Encuentro-Lagunas 2X220 kV
A19: ITCH | J19: P003S008 | K19: 2do C AmpliacionSE_Lagunas220kV
A20: ITCH | J20: P003S009 | K20: 2do C AmpliacionSE_Encuentro220kV
A21: ITCH | J21: P004S001 | K21: ATRs SE Nueva Cardones 500/220kV
A22: ITCH | J22: P004S003 | K22: ATRs SE Nueva Maitencillo 500/220kV
A23: ITCH | J23: P004S005 | K23: ATRs SE Nueva Pan de Azúcar 500/220 kV
A24: ITCH | J24: P005S001 | K24: Ampliación Barras 500 kV SE Nueva Cardones
A25: ITCH | J25: P007S011 | K25: ATR1 DS373 SE Nueva Maitencillo 500/220Kv
A26: ITCH | J26: P008S012 | K26: CS POPL Y STATCOM NPAN 500KV
A27: ITCH | J27: P009S013 | K27: Mando sincronizado ATR
... A30: ITCH | J30: ICO20000 | K30: ACTIVOS EN ALMACEN
A31: TRAN | F31: IC01 | G31: LT 2X500 KV Carrdones Polpaico | J31: ICA10000 | K31: ACTIVOS ADMIN CORP
A32: TRAN | F32: IC02 | G32: Nueva Linea encuentro lagunas | J32: ICO10000 | K32: ACTIVOS ADMIN OYM
A33: TRAN | F33: IC03 | G33: Obra de ampliación tendido seg | J33: ICO20000 | K33: ACTIVOS EN ALMACEN
A34: TRAN | F34: IC04 | G34: Banco de autotransformadores D | J34: P001L001 | K34: Cardones Maitencillo500kV Conexiones220k
A35: TRAN | F35: IC05 | G35: Ampliación barras 500 kv SE NU | J35: P001L002 | K35: Maitencillo Pan DeAzucar500kV Conexiones2
A36: TRAN | F36: IC06 | G36: Diagonal 3 y 4 220kv NMAI NPAN | J36: P001L003 | K36: PanDeAzucar Polpaico500kV Conexiones220k
A37: TRAN | F37: IC07 | G37: Bco autotransormador N1 DS373 | J37: P001S001 | K37: SE Nueva Cardones 500/220kV
A38: TRAN | F38: IC08 | G38: CS POLP Y STATCOM NPAN 500kv | J38: P001S002 | K38: AmpliaciónSECardonesExistente220kV
A39: TRAN | F39: IC09 | G39: Mando sincronizado atr ncar | J39: P001S003 | K39: SE Nueva Maitencillo 500/220kV
A40: TRAN | F40: IC11 | G40: Aumento Capacidad LT220 kV MAI NMAI | J40: P001S004 | K40: AmpliaciónSEMaitencilloExistente220kV
A41: TRAN | F41: IC12 | G41: Ampliación Subestación NPAZ | J41: P001S005 | K41: SE Nueva Pan de Azúcar 500/220 kV
A42: TRAN | F42: ICA1 | G42: ACTIVOS ADMIN CORP | J42: P001S006 | K42: AmpliaciónSEPanDeAzucarExistente220kV
... A44: TRAN | F44: ICO2 | G44: ACTIVOS EN ALMACEN | J44: P002L004 | K44: Encuentro Lagunas 2X220 kV 1Circuito
...

Sheet Ceco
A1: Sociedad | B1: CECO | C1: Responsable | D1: Nombre CECO
A2: ITCH | B2: 10000 | C2: 10000 | D2: GERENCIA GENERAL
A3: ITCH | B3: 10001 | C3: 10001 | D3: ABASTECIMIENTO
A4: ITCH | B4: 10002 | C4: 10002 | D4: ADMINISTRACIÓN
A5: ITCH | B5: 10003 | C5: 10003 | D5: TALENTO ORGANIZ
A6: ITCH | B6: 10004 | C6: 10004 | D6: LEGAL
A7: ITCH | B7: 10005 | C7: 10005 | D7: TI
A8: ITCH | B8: 10006 | C8: 10006 | D8: NUEVOS NEGOCIOS
A9: ITCH | B9: 10007 | C9: 10007 | D9: SST
A10: ITCH | B10: 10008 | C10: 10008 | D10: ESTRATEGIA
A11: ITCH | B11: 10009 | C11: 10009 | D11: ALMACÉN
A12: ITCH | B12: 12000 | C12: 12000 | D12: INCE NUEVOS NEGOCIOS
A13: ITCH | B13: 13000 | C13: 13000 | D13: INNO PROYECTO KILA
... A34: ITCH | B34: 70000 | C34: 70000 | D34: AUDITORÍA INTERNA
A35: ITCH | B35: ANALAG2201 | C35: ANALAG2201 | D35: LT ANA MARÍA
A36: ITCH | B36: ANALAG2202 | C36: ANALAG2202 | D36: LT ANA MARÍA
A37: ITCH | B37: CARD220-M | C37: CARD220-M | D37: MTTO_CAR 220KV
A38: ITCH | B38: CARD220-O | C38: CARD220-O | D38: OP_CAR 220KV
A39: ITCH | B39: CARD2J14PL | C39: CARD2J14PL | D39: PL CAR220
A40: ITCH | B40: CARD2J15PL | C40: CARD2J15PL | D40: PL CAR220
A41: ITCH | B41: CARD2MCOMU | C41: CARD2MCOMU | D41: MC CAR220KV
A42: ITCH | B42: CARNCA2201 | C42: CARNCA2201 | D42: LT CAR
A43: ITCH | B43: CARNCA2202 | C43: CARNCA2202 | D43: LT CAR
A44: ITCH | B44: CIERRE | C44: CIERRE | D44: CIERRE ANUAL
A45: ITCH | B45: ENCANA2201 | C45: ENCANA2201 | D45: LT ENCUENTRO
A46: ITCH | B46: ENCANA2202 | C46: ENCANA2202 | D46: LT ENCUENTRO
... A191: ITCH | B191: NPAN5K0RR1 | C191: NPAN5K0RR1 | D191: MC NPAN500
A192: ITCH | B192: NPAN5K0RR2 | C192: NPAN5K0RR2 | D192: MC NPAN500 | J192: zco:objcostos
A193: ITCH | B193: NPAN5K10CS | C193: NPAN5K10CS | D193: PC NPAN500
A194: ITCH | B194: NPAN5K10MC | C194: NPAN5K10MC | D194: MC NPAN500
A195: ITCH | B195: NPAN5K10PC | C195: NPAN5K10PC | D195: PC NPAN500
A196: ITCH | B196: NPAN5K10PL | C196: NPAN5K10PL | D196: PL NPAN500
A197: ITCH | B197: NPAN5K11ME | C197: NPAN5K11ME | D197: NPAN500
A198: ITCH | B198: NPAN5K12CS | C198: NPAN5K12CS | D198: PC NPAN500
A199: ITCH | B199: NPAN5K12MC | C199: NPAN5K12MC | D199: MC NPAN500
A200: ITCH | B200: NPAN5K12PC | C200: NPAN5K12PC | D200: PC NPAN500
A201: ITCH | B201: NPAN5K12PL | C201: NPAN5K12PL | D201: PL NPAN500
A202: ITCH | B202: NPAN5MCOMU | C202: NPAN5MCOMU | D202: NPAN500
A203: ITCH | B203: NPAN5TRAFR | C203: NPAN5TRAFR | D203: NPAN500
A204: ITCH | B204: NPAPAZ2201 | C204: NPAPAZ2201 | D204: LT NPAN
...

Sheet Emplazamiento
A1: Sociedad | B1: Emplazamiento | C1: Descripción
A2: ITCH | B2: 1101 | C2: Iquique
A3: ITCH | B3: 1107 | C3: Alto Hospicio
A4: ITCH | B4: 1401 | C4: Pozo Almonte
A5: ITCH | B5: 1402 | C5: Camiña
A6: ITCH | B6: 1403 | C6: Colchane
A7: ITCH | B7: 1404 | C7: Huara
A8: ITCH | B8: 1405 | C8: Pica
A9: ITCH | B9: 2101 | C9: Antofagasta
A10: ITCH | B10: 2102 | C10: Mejillones
A11: ITCH | B11: 2103 | C11: Sierra Gorda
A12: ITCH | B12: 2104 | C12: Taltal
A13: ITCH | B13: 2201 | C13: Calama
... A1381: CABA | B1381: 15202 | C1381: General Lagos

Sheet _ListasClase
A1: Descripción Clase (filtrada) | C1: Criterio 1 | E1: Criterio 2 | G1: Criterio 3 | I1: Criterio 4 | K1: Criterio 5 | M1: Emplazamiento | O1: Centro de Costo | Q1: Países | S1: Respuesta SI/NO
A2: {=IFERROR(_xlfn._xlws.FILTER(Clase!$C$2:$C$292, Clase!$A$2:$A$292=Formato!$C$14, ""), "")} -> Terrenos Rurales | C2: {=IFERROR(_xlfn._xlws.FILTER('Criterio '!$B$2:$B$108,'Criterio '!$A$2:$A$108=Formato!$C$14,""),"")} -> 0 | E2: {=IFERROR(_xlfn._xlws.FILTER('Criterio '!$D$2:$D$108,'Criterio '!$A$2:$A$108=Formato!$C$14,""),"")} -> 0 | G2: {=IFERROR(_xlfn._xlws.FILTER('Criterio '!$F$2:$F$108,'Criterio '!$A$2:$A$108=Formato!$C$14,""),"")} -> IC01 | I2: {=IFERROR(_xlfn._xlws.FILTER('Criterio '!$H$2:$H$108,'Criterio '!$A$2:$A$108=Formato!$C$14,""),"")} -> 0 | K2: {=IFERROR(_xlfn._xlws.FILTER('Criterio '!$J$2:$J$108,'Criterio '!$A$2:$A$108=Formato!$C$14,""),"")} -> ICA10000 | M2: {=IFERROR(_xlfn._xlws.FILTER(Emplazamiento!$B$2:$B$1381,Emplazamiento!$A$2:$A$1381=Formato!$C$14,""),"")} -> 1101 | O2: {=IFERROR(_xlfn._xlws.FILTER(Ceco!$B$2:$B$901,Ceco!$A$2:$A$901=Formato!$C$14,""),"")} -> 10000 | Q2: {=IFERROR(_xlfn.UNIQUE(_xlfn._xlws.FILTER(Sociedades!$B$2:$B$10,Sociedades!$B$2:$B$10<>"")),"")} -> Colombia | S2: SI
A3: Terrenos Urbanos | C3: 0 | E3: 0 | G3: IC02 | I3: 0 | K3: ICO10000 | M3: 1107 | O3: 10001 | Q3: Chile | S3: NO
A4: Terrenos Urbanos 2 | C4: 0 | E4: 0 | G4: IC03 | I4: 0 | K4: ICO20000 | M4: 1401 | O4: 10002 | Q4: Perú
A5: Terrenos no explotados - Prop.Inversión | C5: 0 | E5: 0 | G5: IC04 | I5: 0 | K5: P001L001 | M5: 1402 | O5: 10003
A6: Terrenos Urbanos | C6: 0 | E6: 0 | G6: IC05 | I6: 0 | K6: P001L002 | M6: 1403 | O6: 10004
A7: Terrenos Rurales | C7: 0 | E7: 0 | G7: IC06 | I7: 0 | K7: P001L003 | M7: 1404 | O7: 10005
A8: Terrenos no explotados - Prop.Inversión | C8: 0 | E8: 0 | G8: IC07 | I8: 0 | K8: P001S001 | M8: 1405 | O8: 10006
A9: Terrenos Urbanos Leasing | C9: 0 | E9: 0 | G9: IC08 | I9: 0 | K9: P001S002 | M9: 2101 | O9: 10007
A10: Redes, Lineas y Cables (Costos Directos) | C10: 0 | E10: 0 | G10: IC09 | I10: 0 | K10: P001S003 | M10: 2102 | O10: 10008
A11: Redes, Lineas y Cables (Gastos de Adm.Cap. Direc) | C11: 0 | E11: 0 | G11: IC11 | I11: 0 | K11: P001S004 | M11: 2103 | O11: 10009
A12: Redes, Lineas y Cables (Gastos de Adm.Cap. Indirec | C12: 0 | E12: 0 | G12: IC12 | I12: 0 | K12: P001S005 | M12: 2104 | O12: 12000
A13: Redes, Lineas y Cables (Ajustes por Inflacion) | C13: 0 | E13: 0 | G13: ICA1 | I13: 0 | K13: P001S006 | M13: 2201 | O13: 13000
A14: Redes, Lineas y Cables (Gastos Financieros) | C14: 0 | E14: 0 | G14: ICO1 | I14: 0 | K14: P001S007 | M14: 2202 | O14: 13000
A15: Redes, Lineas y Cables (Comisiones Financieras) | C15: 0 | E15: 0 | G15: ICO2 | I15: 0 | K15: P002L004 | M15: 2203 | O15: 20000
A16: Plantas y Ductos (Costos Directos) | C16: 0 | E16: 0 | G16: 0 | I16: 0 | K16: P002S008 | M16: 2301 | O16: 30000
A17: Plantas y Ductos (Gastos de Adm.Cap. Direc) | C17: 0 | E17: 0 | G17: 0 | I17: 0 | K17: P002S009 | M17: 2302 | O17: 30000
A18: Plantas y Ductos (Gastos de Adm.Cap. Indirec) | C18: 0 | E18: 0 | G18: 0 | I18: 0 | K18: P003L004 | M18: 3101 | O18: 30001
A19: Edificaciones (Costos directos) | C19: 0 | E19: 0 | G19: 0 | I19: 0 | K19: P003S008 | M19: 3102 | O19: 30002
A20: Plantas y Ductos (Ajustes por Inflacion) | C20: 0 | E20: 0 | G20: 0 | I20: 0 | K20: P003S009 | M20: 3103 | O20: 30003
A21: Plantas y Ductos (Gastos Financieros) | C21: 0 | E21: 0 | G21: 0 | I21: 0 | K21: P004S001 | M21: 3201 | O21: 40000
A22: Plantas y Ductos (Comisiones Financieras) | C22: 0 | E22: 0 | G22: 0 | I22: 0 | K22: P004S003 | M22: 3202 | O22: 40000
A23: Plantas y Ductos (Costos Directos) Saldo inicial | C23: 0 | E23: 0 | G23: 0 | I23: 0 | K23: P004S005 | M23: 3301 | O23: 40001
A24: Eq de Comun y Computo (Costos Directo) | C24: 0 | E24: 0 | G24: 0 | I24: 0 | K24: P005S001 | M24: 3302 | O24: 40002
A25: Eq de Comun y Computo (Gastos Financieros) | C25: 0 | E25: 0 | G25: 0 | I25: 0 | K25: P007S011 | M25: 3303 | O25: 40003
A26: Eq de Comun y Computo (Gastos de Adm.Cap. Direc) | C26: 0 | E26: 0 | G26: 0 | I26: 0 | K26: P008S012 | M26: 3304 | O26: 40004
A27: Eq de Comun y Computo (Gastos de Adm.Cap. Ind) | C27: 0 | E27: 0 | G27: 0 | I27: 0 | K27: P009S013 | M27: 4101 | O27: 40005
... A30: Redes, Lineas y Cables (Costos Directos) DP | C30: 0 | E30: 0 | G30: 0 | I30: 0 | K30: ICO20000 | M30: 4104 | O30: 60000
A31: Redes, Lineas y Cables (Ajustes por Inflacion)DP | M31: 4105 | O31: 60001
A32: Redes, Lineas y Cables(Gastos de Adm.Cap. Direc)DP | M32: 4106 | O32: 60002
A33: Redes,LineasyCables(Gastos de Adm.Cap. Indirec)DP | M33: 4201 | O33: 60003
A34: Redes, Lineas y Cables (Dif. en Cam Obli Finan) DP | M34: 4202 | O34: 70000
A35: Redes, Lineas y Cables (Gastos Financieros) DP | M35: 4203 | O35: ANALAG2201
A36: Plantas y Ductos (Dif. en Cambio Obli Finan) DP | M36: 4204 | O36: ANALAG2202
A37: Plantas y Ductos (Gastos Financieros) DP | M37: 4301 | O37: CARD220-M
A38: Plantas y Ductos (Gastos de Adm.Cap. Direc) DP | M38: 4302 | O38: CARD220-O
A39: Plantas y Ductos (Gastos de Adm.Cap. Indirec) DP | M39: 4303 | O39: CARD2J14PL
A40: Plantas y Ductos (Ajustes por Inflacion) DP | M40: 4304 | O40: CARD2J15PL
A41: Eq de Comun y Computo (Costos Directo) Ordenes de | M41: 4305 | O41: CARD2MCOMU
A42: Eq de Comun y Computo (Gastos de Adm.Cap. Direc) O | M42: 5101 | O42: CARNCA2201
...

Sheet _Requeridos
A1: CONFIGURACIÓN DE CAMPOS REQUERIDOS POR SOCIEDAD | Z1: [{"reqCol":1,"fmtCol":"C","name":"Orden de Inversión"},{"reqCol":2,"fmtCol":"D","name":"Elemento PEP"},{"reqCol":3,"fmtCol":"E","name":"Pedido"},{"reqCol":4,"fmtCol":"F","name":"Descripción Activo SAP"},{"reqCol":5,"fmtCol":"G","name":"Clase"},{"reqCol":6,"fmtCol":"H","name":"Cantidad"},{"reqCol":7,"fmtCol":"I","name":"Nombre principal AF"},{"reqCol":8,"fmtCol":"L","name":"Fabricante"},{"reqCol":9,"fmtCol":"M","name":"Nit Proveedor"},{"reqCol":10,"fmtCol":"N","name":"Serie"},{"reqCol":11,"fmtCol":"P","name":"Criterio de Clasificación 1"},{"reqCol":12,"fmtCol":"Q","name":"Criterio de Clasificación 2"},{"reqCol":13,"fmtCol":"R","name":"Criterio de Clasificación 3"},{"reqCol":14,"fmtCol":"S","name":"Criterio de Clasificación 4"},{"reqCol":15,"fmtCol":"T","name":"Criterio de Clasificación 5"},{"reqCol":16,"fmtCol":"U","name":"Ubicación técnica"},{"reqCol":17,"fmtCol":"X","name":"Centro"},{"reqCol":18,"fmtCol":"Y","name":"Código País"},{"reqCol":19,"fmtCol":"Z","name":"Emplazamiento"},{"reqCol":20,"fmtCol":"AB","name":"Centro de Costo"},{"reqCol":21,"fmtCol":"AC","name":"Número de personal"},{"reqCol":22,"fmtCol":"AH","name":"Valor Unitario"}]
A3: ℹ️ INSTRUCCIONES:
A4: • En la tabla siguiente, escriba SI en la celda correspondiente a Sociedad + Campo para marcarlo como REQUERIDO.
A5: • Deje en blanco o escriba NO si el campo NO es requerido para esa sociedad.
A6: • Puede agregar nuevas sociedades en nuevas filas siguiendo el mismo formato.
A7: • Los cambios aquí se reflejan automáticamente en la validación del Formato.
A8: Col. Formato → | B8: C | C8: D | D8: E | E8: F | F8: G | G8: H | H8: I | I8: L | J8: M | K8: N | L8: P | M8: Q | N8: R | O8: S | P8: T | Q8: U | R8: X | S8: Y | T8: Z | U8: AB | V8: AC | W8: AH
A9: Sociedad | B9: Orden de Inversión | C9: Elemento PEP | D9: Pedido | E9: Descripción Activo SAP | F9: Clase | G9: Cantidad | H9: Nombre principal AF | I9: Fabricante | J9: Nit Proveedor | K9: Serie | L9: Criterio Clas. 1 | M9: Criterio Clas. 2 | N9: Criterio Clas. 3 | O9: Criterio Clas. 4 | P9: Criterio Clas. 5 | Q9: Ubicación técnica | R9: Centro | S9: Código País | T9: Emplazamiento | U9: Centro de Costo | V9: Número de personal | W9: Valor Unitario
A10: TRAN | B10: SI | C10: SI | E10: SI | F10: SI | G10: SI | H10: SI | N10: SI | P10: SI | R10: SI | T10: SI | U10: SI | W10: SI
A11: ISA | E11: SI | F11: SI | L11: NO | T11: SI
A12: ITCH | B12: SI | C12: SI | E12: SI | F12: SI | G12: SI | H12: SI | N12: SI | P12: SI | R12: SI | T12: SI | U12: SI | W12: SI
A13: CABA | E13: SI | F13: SI | G13: SI | H13: SI | L13: SI | M13: SI | N13: SI | O13: SI | S13: SI | T13: SI | U13: SI | W13: SI
A16: CONFIGURACIÓN PREGUNTAS CHECKLIST POR PAÍS
A17: ℹ️ Escriba SI para mostrar la pregunta en ese país. Deje vacío o NO para ocultarla.
A18: ℹ️ Para agregar un nuevo país: agregue una nueva fila con el nombre del país y sus SI/NO.
A20: País → | B20: P1 | C20: P2 | D20: P3 | E20: P4 | F20: P5 | G20: P6 | H20: P7 | I20: P8 | J20: P9 | K20: P10 | L20: P11
A21: Colombia | B21: SI | C21: SI | D21: SI | E21: SI | F21: SI | G21: SI
A22: Perú | H22: SI | I22: SI | J22: SI | K22: SI | L22: SI
A23: Chile | B23: SI | C23: SI | D23: SI | E23: SI | G23: SI

Sheet Check list
B8: ✅ Checklist de Validación
B11: ✅ Paso 1: Seleccione la PAIS a la cual se realizará la creación de activos.
B12: ✅ Paso 2: Seleccione una respuesta del siguiente listado (SI/NO)
B14: FILIAL | C14: ISA
B17: Preguntas | C17: Respuesta
B18: 1. ¿El activo es un recurso tangible controlado por la compañía? | C18: SI
B19: 2. ¿Se espera que el activo sea utilizado en el giro normal del negocio por más de un año? | C19: SI
B20: 3. ¿Es probable que el activo genere beneficios económicos o apoye funciones administrativas? | C20: SI
B21: 4. ¿Su valor puede ser medido de forma confiable y razonable? | C21: SI
B22: 5. ¿El valor del activo supera 2.5 Salarios Mínimos Mensuales Legales Vigentes (SMMLV)? | C22: SI
B23: 6. ¿Es de interés para la organización, de tal forma que esté dispuesta a realizarle seguimiento y control como propiedad, planta y equipo? | C23: SI
B25: ¿PUEDE SER CREADO COMO ACTIVO FIJO? | C25: =IF(C14="","Seleccione un país válido",IF(COUNTIFS(B18:B23,"<>""",C18:C23,"NO")>0,"NO CUMPLE","CUMPLE")) -> CUMPLE
B27: EXCLUSIVO PARA FILIALES DE PERÚ
B28: 7. ¿El activo supera el valor de 1/4 de UIT (Unidad Impositiva Tributaria)? | C28: SI
B29: 8. ¿El equipo va a ser reemplazado en alguna concesión? | C29: SI
B30: 9. ¿Pertenece a un proyecto? | C30: SI
B31: 10. ¿Se compra a través de una orden estadística según tipo de activo (diversos, inmuebles)? | C31: SI
B32: 11. ¿El activo no está sincronizado AA-PM por la fecha de montaje y esta se reporta al Ministerio/Osinerming? | C32: SI
C34: =IF(C14="","Seleccione un país válido",IF(COUNTIFS(B28:B32,"<>""",C28:C32,"NO")>0,"NO CUMPLE","CUMPLE")) -> CUMPLE
B37: WARNING

Sheet Formato
B11: FORMATO CREACIÓN Y CAPITALIZACIÓN DE ACTIVOS FIJOS
B14: SOCIEDAD: | C14: ISA
B15: FECHA:
B16: ÁREA:
B17: RESPONSABLE DEL ACTIVO FIJO:
B18: LIDER DE ÁREA:
B19: SOLICITUD:
AG20: Aplica solo para Liquidación de Proyectos
B21: Ítem | C21: Orden de Inversión | D21: Elemento PEP | E21: Pedido | F21: Descipción Activo SAP | G21: Clase Clase | H21: Cantidad | I21: Nombre principal del activo fijo | J21: Nombre del activo fijo (información adicional) | K21: Nombre del activo fijo (información adicional) | L21: Fabricante | M21: Nit Proveedor | N21: Serie | O21: Denominación Tipo | P21: Criterio de Clasificación 1 | Q21: Criterio de Clasificación 2 | R21: Criterio de Clasificación 3 | S21: Criterio de Clasificación 4 | T21: Criterio de Clasificación 5 | U21: Ubicación técnica | V21: Activo eléctrico/No Eléctrico | W21: Contrato Conexión/UPME | X21: Centro | Y21: Código País | Z21: Emplazamiento | AA21: Material (Número de Inventario) | AB21: Centro de Costo | AC21: Número de personal | AD21: Centro de Costo Responsable | AE21: Subestación | AF21: Vida Útil Estimada | AG21: Activo Fijo | AH21: Valor Unitario | AI21: Porcentaje | AJ21: Estado de registro
B22: 1 | D22: RI-POAS1-1.2.02 | F22: Equipos de Subestación Nueva Estructura 15 Años | G22: =IFERROR(_xlfn.XLOOKUP(F22,Clase!$C$2:$C$292,Clase!$B$2:$B$292,""),"") -> A451217 | H22: 1 | I22: Controlador campo - Prueba 100 | J22: Controlador campo - Prueba 3 | K22: Controlador campo - Prueba 3 | L22: SIEMENS | N22: BM2501019994 | R22: IC03 | T22: P003S009 | U22: SCAR230M03ME-SASCC | W22: 4510014034 | X22: Tran | Z22: 5603 | AB22: 10004 | AD22: =IFERROR(_xlfn.XLOOKUP(AB22,Ceco!$B$2:$B$901,Ceco!$C$2:$C$901,""),"") -> 10004 | AJ22: =IF(COUNTA(C22,D22,E22,F22,H22,I22,L22,M22,N22,P22,Q22,R22,S22,T22,U22,X22,Y22,Z22,AB22,AC22,AH22)=0,"",IF(LEN(_xlfn.TEXTJOIN(", ",TRUE,IF(AND(_xlfn.XLOOKUP($C$14,_Requeridos!$A$10:$A$20,_Requeridos!$B$10:$B$20,"")="SI",C22=""),"Orden de Inversión",""),IF(AND(_xlfn.XLOOKUP($C$14,_Requeridos!$A$10:$A$20,_Requeridos!$C$10:$C$20,"")="SI",D22=""),"Elemento PEP",""),IF(AND(_xlfn.XLOOKUP($C$14,_Requeridos!$A$10:$A$20,_Requeridos!$D$10:$D$20,"")="SI",E22=""),"Pedido",""),IF(AND(_xlfn.XLOOKUP($C$14,_Requeridos!$A$10:$A$20,_Requeridos!$E$10:$E$20,"")="SI",F22=""),"Descripción Activo SAP",""),IF(AND(_xlfn.XLOOKUP($C$14,_Requeridos!$A$10:$A$20,_Requeridos!$F$10:$F$20,"")="SI",G22=""),"Clase",""),IF(AND(_xlfn.XLOOKUP($C$14,_Requeridos!$A$10:$A$20,_Requeridos!$G$10:$G$20,"")="SI",H22=""),"Cantidad",""),IF(AND(_xlfn.XLOOKUP($C$14,_Requeridos!$A$10:$A$20,_Requeridos!$H$10:$H$20,"")="SI",I22=""),"Nombre principal AF",""),IF(AND(_xlfn.XLOOKUP($C$14,_Requeridos!$A$10:$A$20,_Requeridos!$I$10:$I$20,"")="SI",L22=""),"Fabricante",""),IF(AND(_xlfn.XLOOKUP($C$14,_Requeridos!$A$10:$A$20,_Requeridos!$J$10:$J$20,"")="SI",M22=""),"Nit Proveedor",""),IF(AND(_xlfn.XLOOKUP($C$14,_Requeridos!$A$10:$A$20,_Requeridos!$K$10:$K$20,"")="SI",N22=""),"Serie",""),IF(AND(_xlfn.XLOOKUP($C$14,_Requeridos!$A$10:$A$20,_Requeridos!$L$10:$L$20,"")="SI",P22=""),"Criterio Clas. 1",""),IF(AND(_xlfn.XLOOKUP($C$14,_Requeridos!$A$10:$A$20,_Requeridos!$M$10:$M$20,"")="SI",Q22=""),"Criterio Clas. 2",""),IF(AND(_xlfn.XLOOKUP($C$14,_Requeridos!$A$10:$A$20,_Requeridos!$N$10:$N$20,"")="SI",R22=""),"Criterio Clas. 3",""),IF(AND(_xlfn.XLOOKUP($C$14,_Requeridos!$A$10:$A$20,_Requeridos!$O$10:$O$20,"")="SI",S22=""),"Criterio Clas. 4",""),IF(AND(_xlfn.XLOOKUP($C$14,_Requeridos!$A$10:$A$20,_Requeridos!$P$10:$P$20,"")="SI",T22=""),"Criterio Clas. 5",""),IF(AND(_xlfn.XLOOKUP($C$14,_Requeridos!$A$10:$A$20,_Requeridos!$Q$10:$Q$20,"")="SI",U22=""),"Ubicación técnica",""),IF(AND(_xlfn.XLOOKUP($C$14,_Requeridos!$A$10:$A$20,_Requeridos!$R$10:$R$20,"")="SI",X22=""),"Centro",""),IF(AND(_xlfn.XLOOKUP($C$14,_Requeridos!$A$10:$A$20,_Requeridos!$S$10:$S$20,"")="SI",Y22=""),"Código País",""),IF(AND(_xlfn.XLOOKUP($C$14,_Requeridos!$A$10:$A$20,_Requeridos!$T$10:$T$20,"")="SI",Z22=""),"Emplazamiento",""),IF(AND(_xlfn.XLOOKUP($C$14,_Requeridos!$A$10:$A$20,_Requeridos!$U$10:$U$20,"")="SI",AB22=""),"Centro de Costo",""),IF(AND(_xlfn.XLOOKUP($C$14,_Requeridos!$A$10:$A$20,_Requeridos!$V$10:$V$20,"")="SI",AC22=""),"Número de personal",""),IF(AND(_xlfn.XLOOKUP($C$14,_Requeridos!$A$10:$A$20,_Requeridos!$W$10:$W$20,"")="SI",AH22=""),"Valor Unitario","")))>0,"⚠️ Faltan: "&_xlfn.TEXTJOIN(", ",TRUE,IF(AND(_xlfn.XLOOKUP($C$14,_Requeridos!$A$10:$A$20,_Requeridos!$B$10:$B$20,"")="SI",C22=""),"Orden de Inversión",""),IF(AND(_xlfn.XLOOKUP($C$14,_Requeridos!$A$10:$A$20,_Requeridos!$C$10:$C$20,"")="SI",D22=""),"Elemento PEP",""),IF(AND(_xlfn.XLOOKUP($C$14,_Requeridos!$A$10:$A$20,_Requeridos!$D$10:$D$20,"")="SI",E22=""),"Pedido",""),IF(AND(_xlfn.XLOOKUP($C$14,_Requeridos!$A$10:$A$20,_Requeridos!$E$10:$E$20,"")="SI",F22=""),"Descripción Activo SAP",""),IF(AND(_xlfn.XLOOKUP($C$14,_Requeridos!$A$10:$A$20,_Requeridos!$F$10:$F$20,"")="SI",G22=""),"Clase",""),IF(AND(_xlfn.XLOOKUP($C$14,_Requeridos!$A$10:$A$20,_Requeridos!$G$10:$G$20,"")="SI",H22=""),"Cantidad",""),IF(AND(_xlfn.XLOOKUP($C$14,_Requeridos!$A$10:$A$20,_Requeridos!$H$10:$H$20,"")="SI",I22=""),"Nombre principal AF",""),IF(AND(_xlfn.XLOOKUP($C$14,_Requeridos!$A$10:$A$20,_Requeridos!$I$10:$I$20,"")="SI",L22=""),"Fabricante",""),IF(AND(_xlfn.XLOOKUP($C$14,_Requeridos!$A$10:$A$20,_Requeridos!$J$10:$J$20,"")="SI",M22=""),"Nit Proveedor",""),IF(AND(_xlfn.XLOOKUP($C$14,_Requeridos!$A$10:$A$20,_Requeridos!$K$10:$K$20,"")="SI",N22=""),"Serie",""),IF(AND(_xlfn.XLOOKUP($C$14,_Requeridos!$A$10:$A$20,_Requeridos!$L$10:$L$20,"")="SI",P22=""),"Criterio Clas. 1",""),IF(AND(_xlfn.XLOOKUP($C$14,_Requeridos!$A$10:$A$20,_Requeridos!$M$10:$M$20,"")="SI",Q22=""),"Criterio Clas. 2",""),IF(AND(_xlfn.XLOOKUP($C$14,_Requeridos!$A$10:$A$20,_Requeridos!$N$10:$N$20,"")="SI",R22=""),"Criterio Clas. 3",""),IF(AND(_xlfn.XLOOKUP($C$14,_Requeridos!$A$10:$A$20,_Requeridos!$O$10:$O$20,"")="SI",S22=""),"Criterio Clas. 4",""),IF(AND(_xlfn.XLOOKUP($C$14,_Requeridos!$A$10:$A$20,_Requeridos!$P$10:$P$20,"")="SI",T22=""),"Criterio Clas. 5",""),IF(AND(_xlfn.XLOOKUP($C$14,_Requeridos!$A$10:$A$20,_Requeridos!$Q$10:$Q$20,"")="SI",U22=""),"Ubicación técnica",""),IF(AND(_xlfn.XLOOKUP($C$14,_Requeridos!$A$10:$A$20,_Requeridos!$R$10:$R$20,"")="SI",X22=""),"Centro",""),IF(AND(_xlfn.XLOOKUP($C$14,_Requeridos!$A$10:$A$20,_Requeridos!$S$10:$S$20,"")="SI",Y22=""),"Código País",""),IF(AND(_xlfn.XLOOKUP($C$14,_Requeridos!$A$10:$A$20,_Requeridos!$T$10:$T$20,"")="SI",Z22=""),"Emplazamiento",""),IF(AND(_xlfn.XLOOKUP($C$14,_Requeridos!$A$10:$A$20,_Requeridos!$U$10:$U$20,"")="SI",AB22=""),"Centro de Costo",""),IF(AND(_xlfn.XLOOKUP($C$14,_Requeridos!$A$10:$A$20,_Requeridos!$V$10:$V$20,"")="SI",AC22=""),"Número de personal",""),IF(AND(_xlfn.XLOOKUP($C$14,_Requeridos!$A$10:$A$20,_Requeridos!$W$10:$W$20,"")="SI",AH22=""),"Valor Unitario","")),"✅ Completo")) -> ✅ Completo
B23: 2 | G23: =IFERROR(_xlfn.XLOOKUP(F23,Clase!$C$2:$C$292,Clase!$B$2:$B$292,""),"") | AD23: =IFERROR(_xlfn.XLOOKUP(AB23,Ceco!$B$2:$B$901,Ceco!$C$2:$C$901,""),"") | AJ23: =IF(COUNTA(C23,D23,E23,F23,H23,I23,L23,M23,N23,P23,Q23,R23,S23,T23,U23,X23,Y23,Z23,AB23,AC23,AH23)=0,"",IF(LEN(_xlfn.TEXTJOIN(", ",TRUE,IF(AND(_xlfn.XLOOKUP($C$14,_Requeridos!$A$10:$A$20,_Requeridos!$B$10:$B$20,"")="SI",C23=""),"Orden de Inversión",""),IF(AND(_xlfn.XLOOKUP($C$14,_Requeridos!$A$10:$A$20,_Requeridos!$C$10:$C$20,"")="SI",D23=""),"Elemento PEP",""),IF(AND(_xlfn.XLOOKUP($C$14,_Requeridos!$A$10:$A$20,_Requeridos!$D$10:$D$20,"")="SI",E23=""),"Pedido",""),IF(AND(_xlfn.XLOOKUP($C$14,_Requeridos!$A$10:$A$20,_Requeridos!$E$10:$E$20,"")="SI",F23=""),"Descripción Activo SAP",""),IF(AND(_xlfn.XLOOKUP($C$14,_Requeridos!$A$10:$A$20,_Requeridos!$F$10:$F$20,"")="SI",G23=""),"Clase",""),IF(AND(_xlfn.XLOOKUP($C$14,_Requeridos!$A$10:$A$20,_Requeridos!$G$10:$G$20,"")="SI",H23=""),"Cantidad",""),IF(AND(_xlfn.XLOOKUP($C$14,_Requeridos!$A$10:$A$20,_Requeridos!$H$10:$H$20,"")="SI",I23=""),"Nombre principal AF",""),IF(AND(_xlfn.XLOOKUP($C$14,_Requeridos!$A$10:$A$20,_Requeridos!$I$10:$I$20,"")="SI",L23=""),"Fabricante",""),IF(AND(_xlfn.XLOOKUP($C$14,_Requeridos!$A$10:$A$20,_Requeridos!$J$10:$J$20,"")="SI",M23=""),"Nit Proveedor",""),IF(AND(_xlfn.XLOOKUP($C$14,_Requeridos!$A$10:$A$20,_Requeridos!$K$10:$K$20,"")="SI",N23=""),"Serie",""),IF(AND(_xlfn.XLOOKUP($C$14,_Requeridos!$A$10:$A$20,_Requeridos!$L$10:$L$20,"")="SI",P23=""),"Criterio Clas. 1",""),IF(AND(_xlfn.XLOOKUP($C$14,_Requeridos!$A$10:$A$20,_Requeridos!$M$10:$M$20,"")="SI",Q23=""),"Criterio Clas. 2",""),IF(AND(_xlfn.XLOOKUP($C$14,_Requeridos!$A$10:$A$20,_Requeridos!$N$10:$N$20,"")="SI",R23=""),"Criterio Clas. 3",""),IF(AND(_xlfn.XLOOKUP($C$14,_Requeridos!$A$10:$A$20,_Requeridos!$O$10:$O$20,"")="SI",S23=""),"Criterio Clas. 4",""),IF(AND(_xlfn.XLOOKUP($C$14,_Requeridos!$A$10:$A$20,_Requeridos!$P$10:$P$20,"")="SI",T23=""),"Criterio Clas. 5",""),IF(AND(_xlfn.XLOOKUP($C$14,_Requeridos!$A$10:$A$20,_Requeridos!$Q$10:$Q$20,"")="SI",U23=""),"Ubicación técnica",""),IF(AND(_xlfn.XLOOKUP($C$14,_Requeridos!$A$10:$A$20,_Requeridos!$R$10:$R$20,"")="SI",X23=""),"Centro",""),IF(AND(_xlfn.XLOOKUP($C$14,_Requeridos!$A$10:$A$20,_Requeridos!$S$10:$S$20,"")="SI",Y23=""),"Código País",""),IF(AND(_xlfn.XLOOKUP($C$14,_Requeridos!$A$10:$A$20,_Requeridos!$T$10:$T$20,"")="SI",Z23=""),"Emplazamiento",""),IF(AND(_xlfn.XLOOKUP($C$14,_Requeridos!$A$10:$A$20,_Requeridos!$U$10:$U$20,"")="SI",AB23=""),"Centro de Costo",""),IF(AND(_xlfn.XLOOKUP($C$14,_Requeridos!$A$10:$A$20,_Requeridos!$V$10:$V$20,"")="SI",AC23=""),"Número de personal",""),IF(AND(_xlfn.XLOOKUP($C$14,_Requeridos!$A$10:$A$20,_Requeridos!$W$10:$W$20,"")="SI",AH23=""),"Valor Unitario","")))>0,"⚠️ Faltan: "&_xlfn.TEXTJOIN(", ",TRUE,IF(AND(_xlfn.XLOOKUP($C$14,_Requeridos!$A$10:$A$20,_Requeridos!$B$10:$B$20,"")="SI",C23=""),"Orden de Inversión",""),IF(AND(_xlfn.XLOOKUP($C$14,_Requeridos!$A$10:$A$20,_Requeridos!$C$10:$C$20,"")="SI",D23=""),"Elemento PEP",""),IF(AND(_xlfn.XLOOKUP($C$14,_Requeridos!$A$10:$A$20,_Requeridos!$D$10:$D$20,"")="SI",E23=""),"Pedido",""),IF(AND(_xlfn.XLOOKUP($C$14,_Requeridos!$A$10:$A$20,_Requeridos!$E$10:$E$20,"")="SI",F23=""),"Descripción Activo SAP",""),IF(AND(_xlfn.XLOOKUP($C$14,_Requeridos!$A$10:$A$20,_Requeridos!$F$10:$F$20,"")="SI",G23=""),"Clase",""),IF(AND(_xlfn.XLOOKUP($C$14,_Requeridos!$A$10:$A$20,_Requeridos!$G$10:$G$20,"")="SI",H23=""),"Cantidad",""),IF(AND(_xlfn.XLOOKUP($C$14,_Requeridos!$A$10:$A$20,_Requeridos!$H$10:$H$20,"")="SI",I23=""),"Nombre principal AF",""),IF(AND(_xlfn.XLOOKUP($C$14,_Requeridos!$A$10:$A$20,_Requeridos!$I$10:$I$20,"")="SI",L23=""),"Fabricante",""),IF(AND(_xlfn.XLOOKUP($C$14,_Requeridos!$A$10:$A$20,_Requeridos!$J$10:$J$20,"")="SI",M23=""),"Nit Proveedor",""),IF(AND(_xlfn.XLOOKUP($C$14,_Requeridos!$A$10:$A$20,_Requeridos!$K$10:$K$20,"")="SI",N23=""),"Serie",""),IF(AND(_xlfn.XLOOKUP($C$14,_Requeridos!$A$10:$A$20,_Requeridos!$L$10:$L$20,"")="SI",P23=""),"Criterio Clas. 1",""),IF(AND(_xlfn.XLOOKUP($C$14,_Requeridos!$A$10:$A$20,_Requeridos!$M$10:$M$20,"")="SI",Q23=""),"Criterio Clas. 2",""),IF(AND(_xlfn.XLOOKUP($C$14,_Requeridos!$A$10:$A$20,_Requeridos!$N$10:$N$20,"")="SI",R23=""),"Criterio Clas. 3",""),IF(AND(_xlfn.XLOOKUP($C$14,_Requeridos!$A$10:$A$20,_Requeridos!$O$10:$O$20,"")="SI",S23=""),"Criterio Clas. 4",""),IF(AND(_xlfn.XLOOKUP($C$14,_Requeridos!$A$10:$A$20,_Requeridos!$P$10:$P$20,"")="SI",T23=""),"Criterio Clas. 5",""),IF(AND(_xlfn.XLOOKUP($C$14,_Requeridos!$A$10:$A$20,_Requeridos!$Q$10:$Q$20,"")="SI",U23=""),"Ubicación técnica",""),IF(AND(_xlfn.XLOOKUP($C$14,_Requeridos!$A$10:$A$20,_Requeridos!$R$10:$R$20,"")="SI",X23=""),"Centro",""),IF(AND(_xlfn.XLOOKUP($C$14,_Requeridos!$A$10:$A$20,_Requeridos!$S$10:$S$20,"")="SI",Y23=""),"Código País",""),IF(AND(_xlfn.XLOOKUP($C$14,_Requeridos!$A$10:$A$20,_Requeridos!$T$10:$T$20,"")="SI",Z23=""),"Emplazamiento",""),IF(AND(_xlfn.XLOOKUP($C$14,_Requeridos!$A$10:$A$20,_Requeridos!$U$10:$U$20,"")="SI",AB23=""),"Centro de Costo",""),IF(AND(_xlfn.XLOOKUP($C$14,_Requeridos!$A$10:$A$20,_Requeridos!$V$10:$V$20,"")="SI",AC23=""),"Número de personal",""),IF(AND(_xlfn.XLOOKUP($C$14,_Requeridos!$A$10:$A$20,_Requeridos!$W$10:$W$20,"")="SI",AH23=""),"Valor Unitario","")),"✅ Completo"))
B24: 3 | G24: =IFERROR(_xlfn.XLOOKUP(F24,Clase!$C$2:$C$292,Clase!$B$2:$B$292,""),"") | AD24: =IFERROR(_xlfn.XLOOKUP(AB24,Ceco!$B$2:$B$901,Ceco!$C$2:$C$901,""),"") | AJ24: =IF(COUNTA(C24,D24,E24,F24,H24,I24,L24,M24,N24,P24,Q24,R24,S24,T24,U24,X24,Y24,Z24,AB24,AC24,AH24)=0,"",IF(LEN(_xlfn.TEXTJOIN(", ",TRUE,IF(AND(_xlfn.XLOOKUP($C$14,_Requeridos!$A$10:$A$20,_Requeridos!$B$10:$B$20,"")="SI",C24=""),"Orden de Inversión",""),IF(AND(_xlfn.XLOOKUP($C$14,_Requeridos!$A$10:$A$20,_Requeridos!$C$10:$C$20,"")="SI",D24=""),"Elemento PEP",""),IF(AND(_xlfn.XLOOKUP($C$14,_Requeridos!$A$10:$A$20,_Requeridos!$D$10:$D$20,"")="SI",E24=""),"Pedido",""),IF(AND(_xlfn.XLOOKUP($C$14,_Requeridos!$A$10:$A$20,_Requeridos!$E$10:$E$20,"")="SI",F24=""),"Descripción Activo SAP",""),IF(AND(_xlfn.XLOOKUP($C$14,_Requeridos!$A$10:$A$20,_Requeridos!$F$10:$F$20,"")="SI",G24=""),"Clase",""),IF(AND(_xlfn.XLOOKUP($C$14,_Requeridos!$A$10:$A$20,_Requeridos!$G$10:$G$20,"")="SI",H24=""),"Cantidad",""),IF(AND(_xlfn.XLOOKUP($C$14,_Requeridos!$A$10:$A$20,_Requeridos!$H$10:$H$20,"")="SI",I24=""),"Nombre principal AF",""),IF(AND(_xlfn.XLOOKUP($C$14,_Requeridos!$A$10:$A$20,_Requeridos!$I$10:$I$20,"")="SI",L24=""),"Fabricante",""),IF(AND(_xlfn.XLOOKUP($C$14,_Requeridos!$A$10:$A$20,_Requeridos!$J$10:$J$20,"")="SI",M24=""),"Nit Proveedor",""),IF(AND(_xlfn.XLOOKUP($C$14,_Requeridos!$A$10:$A$20,_Requeridos!$K$10:$K$20,"")="SI",N24=""),"Serie",""),IF(AND(_xlfn.XLOOKUP($C$14,_Requeridos!$A$10:$A$20,_Requeridos!$L$10:$L$20,"")="SI",P24=""),"Criterio Clas. 1",""),IF(AND(_xlfn.XLOOKUP($C$14,_Requeridos!$A$10:$A$20,_Requeridos!$M$10:$M$20,"")="SI",Q24=""),"Criterio Clas. 2",""),IF(AND(_xlfn.XLOOKUP($C$14,_Requeridos!$A$10:$A$20,_Requeridos!$N$10:$N$20,"")="SI",R24=""),"Criterio Clas. 3",""),IF(AND(_xlfn.XLOOKUP($C$14,_Requeridos!$A$10:$A$20,_Requeridos!$O$10:$O$20,"")="SI",S24=""),"Criterio Clas. 4",""),IF(AND(_xlfn.XLOOKUP($C$14,_Requeridos!$A$10:$A$20,_Requeridos!$P$10:$P$20,"")="SI",T24=""),"Criterio Clas. 5",""),IF(AND(_xlfn.XLOOKUP($C$14,_Requeridos!$A$10:$A$20,_Requeridos!$Q$10:$Q$20,"")="SI",U24=""),"Ubicación técnica",""),IF(AND(_xlfn.XLOOKUP($C$14,_Requeridos!$A$10:$A$20,_Requeridos!$R$10:$R$20,"")="SI",X24=""),"Centro",""),IF(AND(_xlfn.XLOOKUP($C$14,_Requeridos!$A$10:$A$20,_Requeridos!$S$10:$S$20,"")="SI",Y24=""),"Código País",""),IF(AND(_xlfn.XLOOKUP($C$14,_Requeridos!$A$10:$A$20,_Requeridos!$T$10:$T$20,"")="SI",Z24=""),"Emplazamiento",""),IF(AND(_xlfn.XLOOKUP($C$14,_Requeridos!$A$10:$A$20,_Requeridos!$U$10:$U$20,"")="SI",AB24=""),"Centro de Costo",""),IF(AND(_xlfn.XLOOKUP($C$14,_Requeridos!$A$10:$A$20,_Requeridos!$V$10:$V$20,"")="SI",AC24=""),"Número de personal",""),IF(AND(_xlfn.XLOOKUP($C$14,_Requeridos!$A$10:$A$20,_Requeridos!$W$10:$W$20,"")="SI",AH24=""),"Valor Unitario","")))>0,"⚠️ Faltan: "&_xlfn.TEXTJOIN(", ",TRUE,IF(AND(_xlfn.XLOOKUP($C$14,_Requeridos!$A$10:$A$20,_Requeridos!$B$10:$B$20,"")="SI",C24=""),"Orden de Inversión",""),IF(AND(_xlfn.XLOOKUP($C$14,_Requeridos!$A$10:$A$20,_Requeridos!$C$10:$C$20,"")="SI",D24=""),"Elemento PEP",""),IF(AND(_xlfn.XLOOKUP($C$14,_Requeridos!$A$10:$A$20,_Requeridos!$D$10:$D$20,"")="SI",E24=""),"Pedido",""),IF(AND(_xlfn.XLOOKUP($C$14,_Requeridos!$A$10:$A$20,_Requeridos!$E$10:$E$20,"")="SI",F24=""),"Descripción Activo SAP",""),IF(AND(_xlfn.XLOOKUP($C$14,_Requeridos!$A$10:$A$20,_Requeridos!$F$10:$F$20,"")="SI",G24=""),"Clase",""),IF(AND(_xlfn.XLOOKUP($C$14,_Requeridos!$A$10:$A$20,_Requeridos!$G$10:$G$20,"")="SI",H24=""),"Cantidad",""),IF(AND(_xlfn.XLOOKUP($C$14,_Requeridos!$A$10:$A$20,_Requeridos!$H$10:$H$20,"")="SI",I24=""),"Nombre principal AF",""),IF(AND(_xlfn.XLOOKUP($C$14,_Requeridos!$A$10:$A$20,_Requeridos!$I$10:$I$20,"")="SI",L24=""),"Fabricante",""),IF(AND(_xlfn.XLOOKUP($C$14,_Requeridos!$A$10:$A$20,_Requeridos!$J$10:$J$20,"")="SI",M24=""),"Nit Proveedor",""),IF(AND(_xlfn.XLOOKUP($C$14,_Requeridos!$A$10:$A$20,_Requeridos!$K$10:$K$20,"")="SI",N24=""),"Serie",""),IF(AND(_xlfn.XLOOKUP($C$14,_Requeridos!$A$10:$A$20,_Requeridos!$L$10:$L$20,"")="SI",P24=""),"Criterio Clas. 1",""),IF(AND(_xlfn.XLOOKUP($C$14,_Requeridos!$A$10:$A$20,_Requeridos!$M$10:$M$20,"")="SI",Q24=""),"Criterio Clas. 2",""),IF(AND(_xlfn.XLOOKUP($C$14,_Requeridos!$A$10:$A$20,_Requeridos!$N$10:$N$20,"")="SI",R24=""),"Criterio Clas. 3",""),IF(AND(_xlfn.XLOOKUP($C$14,_Requeridos!$A$10:$A$20,_Requeridos!$O$10:$O$20,"")="SI",S24=""),"Criterio Clas. 4",""),IF(AND(_xlfn.XLOOKUP($C$14,_Requeridos!$A$10:$A$20,_Requeridos!$P$10:$P$20,"")="SI",T24=""),"Criterio Clas. 5",""),IF(AND(_xlfn.XLOOKUP($C$14,_Requeridos!$A$10:$A$20,_Requeridos!$Q$10:$Q$20,"")="SI",U24=""),"Ubicación técnica",""),IF(AND(_xlfn.XLOOKUP($C$14,_Requeridos!$A$10:$A$20,_Requeridos!$R$10:$R$20,"")="SI",X24=""),"Centro",""),IF(AND(_xlfn.XLOOKUP($C$14,_Requeridos!$A$10:$A$20,_Requeridos!$S$10:$S$20,"")="SI",Y24=""),"Código País",""),IF(AND(_xlfn.XLOOKUP($C$14,_Requeridos!$A$10:$A$20,_Requeridos!$T$10:$T$20,"")="SI",Z24=""),"Emplazamiento",""),IF(AND(_xlfn.XLOOKUP($C$14,_Requeridos!$A$10:$A$20,_Requeridos!$U$10:$U$20,"")="SI",AB24=""),"Centro de Costo",""),IF(AND(_xlfn.XLOOKUP($C$14,_Requeridos!$A$10:$A$20,_Requeridos!$V$10:$V$20,"")="SI",AC24=""),"Número de personal",""),IF(AND(_xlfn.XLOOKUP($C$14,_Requeridos!$A$10:$A$20,_Requeridos!$W$10:$W$20,"")="SI",AH24=""),"Valor Unitario","")),"✅ Completo"))
B25: 4 | G25: =IFERROR(_xlfn.XLOOKUP(F25,Clase!$C$2:$C$292,Clase!$B$2:$B$292,""),"") | AD25: =IFERROR(_xlfn.XLOOKUP(AB25,Ceco!$B$2:$B$901,Ceco!$C$2:$C$901,""),"") | AJ25: =IF(COUNTA(C25,D25,E25,F25,H25,I25,L25,M25,N25,P25,Q25,R25,S25,T25,U25,X25,Y25,Z25,AB25,AC25,AH25)=0,"",IF(LEN(_xlfn.TEXTJOIN(", ",TRUE,IF(AND(_xlfn.XLOOKUP($C$14,_Requeridos!$A$10:$A$20,_Requeridos!$B$10:$B$20,"")="SI",C25=""),"Orden de Inversión",""),IF(AND(_xlfn.XLOOKUP($C$14,_Requeridos!$A$10:$A$20,_Requeridos!$C$10:$C$20,"")="SI",D25=""),"Elemento PEP",""),IF(AND(_xlfn.XLOOKUP($C$14,_Requeridos!$A$10:$A$20,_Requeridos!$D$10:$D$20,"")="SI",E25=""),"Pedido",""),IF(AND(_xlfn.XLOOKUP($C$14,_Requeridos!$A$10:$A$20,_Requeridos!$E$10:$E$20,"")="SI",F25=""),"Descripción Activo SAP",""),IF(AND(_xlfn.XLOOKUP($C$14,_Requeridos!$A$10:$A$20,_Requeridos!$F$10:$F$20,"")="SI",G25=""),"Clase",""),IF(AND(_xlfn.XLOOKUP($C$14,_Requeridos!$A$10:$A$20,_Requeridos!$G$10:$G$20,"")="SI",H25=""),"Cantidad",""),IF(AND(_xlfn.XLOOKUP($C$14,_Requeridos!$A$10:$A$20,_Requeridos!$H$10:$H$20,"")="SI",I25=""),"Nombre principal AF",""),IF(AND(_xlfn.XLOOKUP($C$14,_Requeridos!$A$10:$A$20,_Requeridos!$I$10:$I$20,"")="SI",L25=""),"Fabricante",""),IF(AND(_xlfn.XLOOKUP($C$14,_Requeridos!$A$10:$A$20,_Requeridos!$J$10:$J$20,"")="SI",M25=""),"Nit Proveedor",""),IF(AND(_xlfn.XLOOKUP($C$14,_Requeridos!$A$10:$A$20,_Requeridos!$K$10:$K$20,"")="SI",N25=""),"Serie",""),IF(AND(_xlfn.XLOOKUP($C$14,_Requeridos!$A$10:$A$20,_Requeridos!$L$10:$L$20,"")="SI",P25=""),"Criterio Clas. 1",""),IF(AND(_xlfn.XLOOKUP($C$14,_Requeridos!$A$10:$A$20,_Requeridos!$M$10:$M$20,"")="SI",Q25=""),"Criterio Clas. 2",""),IF(AND(_xlfn.XLOOKUP($C$14,_Requeridos!$A$10:$A$20,_Requeridos!$N$10:$N$20,"")="SI",R25=""),"Criterio Clas. 3",""),IF(AND(_xlfn.XLOOKUP($C$14,_Requeridos!$A$10:$A$20,_Requeridos!$O$10:$O$20,"")="SI",S25=""),"Criterio Clas. 4",""),IF(AND(_xlfn.XLOOKUP($C$14,_Requeridos!$A$10:$A$20,_Requeridos!$P$10:$P$20,"")="SI",T25=""),"Criterio Clas. 5",""),IF(AND(_xlfn.XLOOKUP($C$14,_Requeridos!$A$10:$A$20,_Requeridos!$Q$10:$Q$20,"")="SI",U25=""),"Ubicación técnica",""),IF(AND(_xlfn.XLOOKUP($C$14,_Requeridos!$A$10:$A$20,_Requeridos!$R$10:$R$20,"")="SI",X25=""),"Centro",""),IF(AND(_xlfn.XLOOKUP($C$14,_Requeridos!$A$10:$A$20,_Requeridos!$S$10:$S$20,"")="SI",Y25=""),"Código País",""),IF(AND(_xlfn.XLOOKUP($C$14,_Requeridos!$A$10:$A$20,_Requeridos!$T$10:$T$20,"")="SI",Z25=""),"Emplazamiento",""),IF(AND(_xlfn.XLOOKUP($C$14,_Requeridos!$A$10:$A$20,_Requeridos!$U$10:$U$20,"")="SI",AB25=""),"Centro de Costo",""),IF(AND(_xlfn.XLOOKUP($C$14,_Requeridos!$A$10:$A$20,_Requeridos!$V$10:$V$20,"")="SI",AC25=""),"Número de personal",""),IF(AND(_xlfn.XLOOKUP($C$14,_Requeridos!$A$10:$A$20,_Requeridos!$W$10:$W$20,"")="SI",AH25=""),"Valor Unitario","")))>0,"⚠️ Faltan: "&_xlfn.TEXTJOIN(", ",TRUE,IF(AND(_xlfn.XLOOKUP($C$14,_Requeridos!$A$10:$A$20,_Requeridos!$B$10:$B$20,"")="SI",C25=""),"Orden de Inversión",""),IF(AND(_xlfn.XLOOKUP($C$14,_Requeridos!$A$10:$A$20,_Requeridos!$C$10:$C$20,"")="SI",D25=""),"Elemento PEP",""),IF(AND(_xlfn.XLOOKUP($C$14,_Requeridos!$A$10:$A$20,_Requeridos!$D$10:$D$20,"")="SI",E25=""),"Pedido",""),IF(AND(_xlfn.XLOOKUP($C$14,_Requeridos!$A$10:$A$20,_Requeridos!$E$10:$E$20,"")="SI",F25=""),"Descripción Activo SAP",""),IF(AND(_xlfn.XLOOKUP($C$14,_Requeridos!$A$10:$A$20,_Requeridos!$F$10:$F$20,"")="SI",G25=""),"Clase",""),IF(AND(_xlfn.XLOOKUP($C$14,_Requeridos!$A$10:$A$20,_Requeridos!$G$10:$G$20,"")="SI",H25=""),"Cantidad",""),IF(AND(_xlfn.XLOOKUP($C$14,_Requeridos!$A$10:$A$20,_Requeridos!$H$10:$H$20,"")="SI",I25=""),"Nombre principal AF",""),IF(AND(_xlfn.XLOOKUP($C$14,_Requeridos!$A$10:$A$20,_Requeridos!$I$10:$I$20,"")="SI",L25=""),"Fabricante",""),IF(AND(_xlfn.XLOOKUP($C$14,_Requeridos!$A$10:$A$20,_Requeridos!$J$10:$J$20,"")="SI",M25=""),"Nit Proveedor",""),IF(AND(_xlfn.XLOOKUP($C$14,_Requeridos!$A$10:$A$20,_Requeridos!$K$10:$K$20,"")="SI",N25=""),"Serie",""),IF(AND(_xlfn.XLOOKUP($C$14,_Requeridos!$A$10:$A$20,_Requeridos!$L$10:$L$20,"")="SI",P25=""),"Criterio Clas. 1",""),IF(AND(_xlfn.XLOOKUP($C$14,_Requeridos!$A$10:$A$20,_Requeridos!$M$10:$M$20,"")="SI",Q25=""),"Criterio Clas. 2",""),IF(AND(_xlfn.XLOOKUP($C$14,_Requeridos!$A$10:$A$20,_Requeridos!$N$10:$N$20,"")="SI",R25=""),"Criterio Clas. 3",""),IF(AND(_xlfn.XLOOKUP($C$14,_Requeridos!$A$10:$A$20,_Requeridos!$O$10:$O$20,"")="SI",S25=""),"Criterio Clas. 4",""),IF(AND(_xlfn.XLOOKUP($C$14,_Requeridos!$A$10:$A$20,_Requeridos!$P$10:$P$20,"")="SI",T25=""),"Criterio Clas. 5",""),IF(AND(_xlfn.XLOOKUP($C$14,_Requeridos!$A$10:$A$20,_Requeridos!$Q$10:$Q$20,"")="SI",U25=""),"Ubicación técnica",""),IF(AND(_xlfn.XLOOKUP($C$14,_Requeridos!$A$10:$A$20,_Requeridos!$R$10:$R$20,"")="SI",X25=""),"Centro",""),IF(AND(_xlfn.XLOOKUP($C$14,_Requeridos!$A$10:$A$20,_Requeridos!$S$10:$S$20,"")="SI",Y25=""),"Código País",""),IF(AND(_xlfn.XLOOKUP($C$14,_Requeridos!$A$10:$A$20,_Requeridos!$T$10:$T$20,"")="SI",Z25=""),"Emplazamiento",""),IF(AND(_xlfn.XLOOKUP($C$14,_Requeridos!$A$10:$A$20,_Requeridos!$U$10:$U$20,"")="SI",AB25=""),"Centro de Costo",""),IF(AND(_xlfn.XLOOKUP($C$14,_Requeridos!$A$10:$A$20,_Requeridos!$V$10:$V$20,"")="SI",AC25=""),"Número de personal",""),IF(AND(_xlfn.XLOOKUP($C$14,_Requeridos!$A$10:$A$20,_Requeridos!$W$10:$W$20,"")="SI",AH25=""),"Valor Unitario","")),"✅ Completo"))
B26: 5 | G26: =IFERROR(_xlfn.XLOOKUP(F26,Clase!$C$2:$C$292,Clase!$B$2:$B$292,""),"") | AD26: =IFERROR(_xlfn.XLOOKUP(AB26,Ceco!$B$2:$B$901,Ceco!$C$2:$C$901,""),"") | AJ26: =IF(COUNTA(C26,D26,E26,F26,H26,I26,L26,M26,N26,P26,Q26,R26,S26,T26,U26,X26,Y26,Z26,AB26,AC26,AH26)=0,"",IF(LEN(_xlfn.TEXTJOIN(", ",TRUE,IF(AND(_xlfn.XLOOKUP($C$14,_Requeridos!$A$10:$A$20,_Requeridos!$B$10:$B$20,"")="SI",C26=""),"Orden de Inversión",""),IF(AND(_xlfn.XLOOKUP($C$14,_Requeridos!$A$10:$A$20,_Requeridos!$C$10:$C$20,"")="SI",D26=""),"Elemento PEP",""),IF(AND(_xlfn.XLOOKUP($C$14,_Requeridos!$A$10:$A$20,_Requeridos!$D$10:$D$20,"")="SI",E26=""),"Pedido",""),IF(AND(_xlfn.XLOOKUP($C$14,_Requeridos!$A$10:$A$20,_Requeridos!$E$10:$E$20,"")="SI",F26=""),"Descripción Activo SAP",""),IF(AND(_xlfn.XLOOKUP($C$14,_Requeridos!$A$10:$A$20,_Requeridos!$F$10:$F$20,"")="SI",G26=""),"Clase",""),IF(AND(_xlfn.XLOOKUP($C$14,_Requeridos!$A$10:$A$20,_Requeridos!$G$10:$G$20,"")="SI",H26=""),"Cantidad",""),IF(AND(_xlfn.XLOOKUP($C$14,_Requeridos!$A$10:$A$20,_Requeridos!$H$10:$H$20,"")="SI",I26=""),"Nombre principal AF",""),IF(AND(_xlfn.XLOOKUP($C$14,_Requeridos!$A$10:$A$20,_Requeridos!$I$10:$I$20,"")="SI",L26=""),"Fabricante",""),IF(AND(_xlfn.XLOOKUP($C$14,_Requeridos!$A$10:$A$20,_Requeridos!$J$10:$J$20,"")="SI",M26=""),"Nit Proveedor",""),IF(AND(_xlfn.XLOOKUP($C$14,_Requeridos!$A$10:$A$20,_Requeridos!$K$10:$K$20,"")="SI",N26=""),"Serie",""),IF(AND(_xlfn.XLOOKUP($C$14,_Requeridos!$A$10:$A$20,_Requeridos!$L$10:$L$20,"")="SI",P26=""),"Criterio Clas. 1",""),IF(AND(_xlfn.XLOOKUP($C$14,_Requeridos!$A$10:$A$20,_Requeridos!$M$10:$M$20,"")="SI",Q26=""),"Criterio Clas. 2",""),IF(AND(_xlfn.XLOOKUP($C$14,_Requeridos!$A$10:$A$20,_Requeridos!$N$10:$N$20,"")="SI",R26=""),"Criterio Clas. 3",""),IF(AND(_xlfn.XLOOKUP($C$14,_Requeridos!$A$10:$A$20,_Requeridos!$O$10:$O$20,"")="SI",S26=""),"Criterio Clas. 4",""),IF(AND(_xlfn.XLOOKUP($C$14,_Requeridos!$A$10:$A$20,_Requeridos!$P$10:$P$20,"")="SI",T26=""),"Criterio Clas. 5",""),IF(AND(_xlfn.XLOOKUP($C$14,_Requeridos!$A$10:$A$20,_Requeridos!$Q$10:$Q$20,"")="SI",U26=""),"Ubicación técnica",""),IF(AND(_xlfn.XLOOKUP($C$14,_Requeridos!$A$10:$A$20,_Requeridos!$R$10:$R$20,"")="SI",X26=""),"Centro",""),IF(AND(_xlfn.XLOOKUP($C$14,_Requeridos!$A$10:$A$20,_Requeridos!$S$10:$S$20,"")="SI",Y26=""),"Código País",""),IF(AND(_xlfn.XLOOKUP($C$14,_Requeridos!$A$10:$A$20,_Requeridos!$T$10:$T$20,"")="SI",Z26=""),"Emplazamiento",""),IF(AND(_xlfn.XLOOKUP($C$14,_Requeridos!$A$10:$A$20,_Requeridos!$U$10:$U$20,"")="SI",AB26=""),"Centro de Costo",""),IF(AND(_xlfn.XLOOKUP($C$14,_Requeridos!$A$10:$A$20,_Requeridos!$V$10:$V$20,"")="SI",AC26=""),"Número de personal",""),IF(AND(_xlfn.XLOOKUP($C$14,_Requeridos!$A$10:$A$20,_Requeridos!$W$10:$W$20,"")="SI",AH26=""),"Valor Unitario","")))>0,"⚠️ Faltan: "&_xlfn.TEXTJOIN(", ",TRUE,IF(AND(_xlfn.XLOOKUP($C$14,_Requeridos!$A$10:$A$20,_Requeridos!$B$10:$B$20,"")="SI",C26=""),"Orden de Inversión",""),IF(AND(_xlfn.XLOOKUP($C$14,_Requeridos!$A$10:$A$20,_Requeridos!$C$10:$C$20,"")="SI",D26=""),"Elemento PEP",""),IF(AND(_xlfn.XLOOKUP($C$14,_Requeridos!$A$10:$A$20,_Requeridos!$D$10:$D$20,"")="SI",E26=""),"Pedido",""),IF(AND(_xlfn.XLOOKUP($C$14,_Requeridos!$A$10:$A$20,_Requeridos!$E$10:$E$20,"")="SI",F26=""),"Descripción Activo SAP",""),IF(AND(_xlfn.XLOOKUP($C$14,_Requeridos!$A$10:$A$20,_Requeridos!$F$10:$F$20,"")="SI",G26=""),"Clase",""),IF(AND(_xlfn.XLOOKUP($C$14,_Requeridos!$A$10:$A$20,_Requeridos!$G$10:$G$20,"")="SI",H26=""),"Cantidad",""),IF(AND(_xlfn.XLOOKUP($C$14,_Requeridos!$A$10:$A$20,_Requeridos!$H$10:$H$20,"")="SI",I26=""),"Nombre principal AF",""),IF(AND(_xlfn.XLOOKUP($C$14,_Requeridos!$A$10:$A$20,_Requeridos!$I$10:$I$20,"")="SI",L26=""),"Fabricante",""),IF(AND(_xlfn.XLOOKUP($C$14,_Requeridos!$A$10:$A$20,_Requeridos!$J$10:$J$20,"")="SI",M26=""),"Nit Proveedor",""),IF(AND(_xlfn.XLOOKUP($C$14,_Requeridos!$A$10:$A$20,_Requeridos!$K$10:$K$20,"")="SI",N26=""),"Serie",""),IF(AND(_xlfn.XLOOKUP($C$14,_Requeridos!$A$10:$A$20,_Requeridos!$L$10:$L$20,"")="SI",P26=""),"Criterio Clas. 1",""),IF(AND(_xlfn.XLOOKUP($C$14,_Requeridos!$A$10:$A$20,_Requeridos!$M$10:$M$20,"")="SI",Q26=""),"Criterio Clas. 2",""),IF(AND(_xlfn.XLOOKUP($C$14,_Requeridos!$A$10:$A$20,_Requeridos!$N$10:$N$20,"")="SI",R26=""),"Criterio Clas. 3",""),IF(AND(_xlfn.XLOOKUP($C$14,_Requeridos!$A$10:$A$20,_Requeridos!$O$10:$O$20,"")="SI",S26=""),"Criterio Clas. 4",""),IF(AND(_xlfn.XLOOKUP($C$14,_Requeridos!$A$10:$A$20,_Requeridos!$P$10:$P$20,"")="SI",T26=""),"Criterio Clas. 5",""),IF(AND(_xlfn.XLOOKUP($C$14,_Requeridos!$A$10:$A$20,_Requeridos!$Q$10:$Q$20,"")="SI",U26=""),"Ubicación técnica",""),IF(AND(_xlfn.XLOOKUP($C$14,_Requeridos!$A$10:$A$20,_Requeridos!$R$10:$R$20,"")="SI",X26=""),"Centro",""),IF(AND(_xlfn.XLOOKUP($C$14,_Requeridos!$A$10:$A$20,_Requeridos!$S$10:$S$20,"")="SI",Y26=""),"Código País",""),IF(AND(_xlfn.XLOOKUP($C$14,_Requeridos!$A$10:$A$20,_Requeridos!$T$10:$T$20,"")="SI",Z26=""),"Emplazamiento",""),IF(AND(_xlfn.XLOOKUP($C$14,_Requeridos!$A$10:$A$20,_Requeridos!$U$10:$U$20,"")="SI",AB26=""),"Centro de Costo",""),IF(AND(_xlfn.XLOOKUP($C$14,_Requeridos!$A$10:$A$20,_Requeridos!$V$10:$V$20,"")="SI",AC26=""),"Número de personal",""),IF(AND(_xlfn.XLOOKUP($C$14,_Requeridos!$A$10:$A$20,_Requeridos!$W$10:$W$20,"")="SI",AH26=""),"Valor Unitario","")),"✅ Completo"))
B27: 6 | G27: =IFERROR(_xlfn.XLOOKUP(F27,Clase!$C$2:$C$292,Clase!$B$2:$B$292,""),"") | AD27: =IFERROR(_xlfn.XLOOKUP(AB27,Ceco!$B$2:$B$901,Ceco!$C$2:$C$901,""),"") | AJ27: =IF(COUNTA(C27,D27,E27,F27,H27,I27,L27,M27,N27,P27,Q27,R27,S27,T27,U27,X27,Y27,Z27,AB27,AC27,AH27)=0,"",IF(LEN(_xlfn.TEXTJOIN(", ",TRUE,IF(AND(_xlfn.XLOOKUP($C$14,_Requeridos!$A$10:$A$20,_Requeridos!$B$10:$B$20,"")="SI",C27=""),"Orden de Inversión",""),IF(AND(_xlfn.XLOOKUP($C$14,_Requeridos!$A$10:$A$20,_Requeridos!$C$10:$C$20,"")="SI",D27=""),"Elemento PEP",""),IF(AND(_xlfn.XLOOKUP($C$14,_Requeridos!$A$10:$A$20,_Requeridos!$D$10:$D$20,"")="SI",E27=""),"Pedido",""),IF(AND(_xlfn.XLOOKUP($C$14,_Requeridos!$A$10:$A$20,_Requeridos!$E$10:$E$20,"")="SI",F27=""),"Descripción Activo SAP",""),IF(AND(_xlfn.XLOOKUP($C$14,_Requeridos!$A$10:$A$20,_Requeridos!$F$10:$F$20,"")="SI",G27=""),"Clase",""),IF(AND(_xlfn.XLOOKUP($C$14,_Requeridos!$A$10:$A$20,_Requeridos!$G$10:$G$20,"")="SI",H27=""),"Cantidad",""),IF(AND(_xlfn.XLOOKUP($C$14,_Requeridos!$A$10:$A$20,_Requeridos!$H$10:$H$20,"")="SI",I27=""),"Nombre principal AF",""),IF(AND(_xlfn.XLOOKUP($C$14,_Requeridos!$A$10:$A$20,_Requeridos!$I$10:$I$20,"")="SI",L27=""),"Fabricante",""),IF(AND(_xlfn.XLOOKUP($C$14,_Requeridos!$A$10:$A$20,_Requeridos!$J$10:$J$20,"")="SI",M27=""),"Nit Proveedor",""),IF(AND(_xlfn.XLOOKUP($C$14,_Requeridos!$A$10:$A$20,_Requeridos!$K$10:$K$20,"")="SI",N27=""),"Serie",""),IF(AND(_xlfn.XLOOKUP($C$14,_Requeridos!$A$10:$A$20,_Requeridos!$L$10:$L$20,"")="SI",P27=""),"Criterio Clas. 1",""),IF(AND(_xlfn.XLOOKUP($C$14,_Requeridos!$A$10:$A$20,_Requeridos!$M$10:$M$20,"")="SI",Q27=""),"Criterio Clas. 2",""),IF(AND(_xlfn.XLOOKUP($C$14,_Requeridos!$A$10:$A$20,_Requeridos!$N$10:$N$20,"")="SI",R27=""),"Criterio Clas. 3",""),IF(AND(_xlfn.XLOOKUP($C$14,_Requeridos!$A$10:$A$20,_Requeridos!$O$10:$O$20,"")="SI",S27=""),"Criterio Clas. 4",""),IF(AND(_xlfn.XLOOKUP($C$14,_Requeridos!$A$10:$A$20,_Requeridos!$P$10:$P$20,"")="SI",T27=""),"Criterio Clas. 5",""),IF(AND(_xlfn.XLOOKUP($C$14,_Requeridos!$A$10:$A$20,_Requeridos!$Q$10:$Q$20,"")="SI",U27=""),"Ubicación técnica",""),IF(AND(_xlfn.XLOOKUP($C$14,_Requeridos!$A$10:$A$20,_Requeridos!$R$10:$R$20,"")="SI",X27=""),"Centro",""),IF(AND(_xlfn.XLOOKUP($C$14,_Requeridos!$A$10:$A$20,_Requeridos!$S$10:$S$20,"")="SI",Y27=""),"Código País",""),IF(AND(_xlfn.XLOOKUP($C$14,_Requeridos!$A$10:$A$20,_Requeridos!$T$10:$T$20,"")="SI",Z27=""),"Emplazamiento",""),IF(AND(_xlfn.XLOOKUP($C$14,_Requeridos!$A$10:$A$20,_Requeridos!$U$10:$U$20,"")="SI",AB27=""),"Centro de Costo",""),IF(AND(_xlfn.XLOOKUP($C$14,_Requeridos!$A$10:$A$20,_Requeridos!$V$10:$V$20,"")="SI",AC27=""),"Número de personal",""),IF(AND(_xlfn.XLOOKUP($C$14,_Requeridos!$A$10:$A$20,_Requeridos!$W$10:$W$20,"")="SI",AH27=""),"Valor Unitario","")))>0,"⚠️ Faltan: "&_xlfn.TEXTJOIN(", ",TRUE,IF(AND(_xlfn.XLOOKUP($C$14,_Requeridos!$A$10:$A$20,_Requeridos!$B$10:$B$20,"")="SI",C27=""),"Orden de Inversión",""),IF(AND(_xlfn.XLOOKUP($C$14,_Requeridos!$A$10:$A$20,_Requeridos!$C$10:$C$20,"")="SI",D27=""),"Elemento PEP",""),IF(AND(_xlfn.XLOOKUP($C$14,_Requeridos!$A$10:$A$20,_Requeridos!$D$10:$D$20,"")="SI",E27=""),"Pedido",""),IF(AND(_xlfn.XLOOKUP($C$14,_Requeridos!$A$10:$A$20,_Requeridos!$E$10:$E$20,"")="SI",F27=""),"Descripción Activo SAP",""),IF(AND(_xlfn.XLOOKUP($C$14,_Requeridos!$A$10:$A$20,_Requeridos!$F$10:$F$20,"")="SI",G27=""),"Clase",""),IF(AND(_xlfn.XLOOKUP($C$14,_Requeridos!$A$10:$A$20,_Requeridos!$G$10:$G$20,"")="SI",H27=""),"Cantidad",""),IF(AND(_xlfn.XLOOKUP($C$14,_Requeridos!$A$10:$A$20,_Requeridos!$H$10:$H$20,"")="SI",I27=""),"Nombre principal AF",""),IF(AND(_xlfn.XLOOKUP($C$14,_Requeridos!$A$10:$A$20,_Requeridos!$I$10:$I$20,"")="SI",L27=""),"Fabricante",""),IF(AND(_xlfn.XLOOKUP($C$14,_Requeridos!$A$10:$A$20,_Requeridos!$J$10:$J$20,"")="SI",M27=""),"Nit Proveedor",""),IF(AND(_xlfn.XLOOKUP($C$14,_Requeridos!$A$10:$A$20,_Requeridos!$K$10:$K$20,"")="SI",N27=""),"Serie",""),IF(AND(_xlfn.XLOOKUP($C$14,_Requeridos!$A$10:$A$20,_Requeridos!$L$10:$L$20,"")="SI",P27=""),"Criterio Clas. 1",""),IF(AND(_xlfn.XLOOKUP($C$14,_Requeridos!$A$10:$A$20,_Requeridos!$M$10:$M$20,"")="SI",Q27=""),"Criterio Clas. 2",""),IF(AND(_xlfn.XLOOKUP($C$14,_Requeridos!$A$10:$A$20,_Requeridos!$N$10:$N$20,"")="SI",R27=""),"Criterio Clas. 3",""),IF(AND(_xlfn.XLOOKUP($C$14,_Requeridos!$A$10:$A$20,_Requeridos!$O$10:$O$20,"")="SI",S27=""),"Criterio Clas. 4",""),IF(AND(_xlfn.XLOOKUP($C$14,_Requeridos!$A$10:$A$20,_Requeridos!$P$10:$P$20,"")="SI",T27=""),"Criterio Clas. 5",""),IF(AND(_xlfn.XLOOKUP($C$14,_Requeridos!$A$10:$A$20,_Requeridos!$Q$10:$Q$20,"")="SI",U27=""),"Ubicación técnica",""),IF(AND(_xlfn.XLOOKUP($C$14,_Requeridos!$A$10:$A$20,_Requeridos!$R$10:$R$20,"")="SI",X27=""),"Centro",""),IF(AND(_xlfn.XLOOKUP($C$14,_Requeridos!$A$10:$A$20,_Requeridos!$S$10:$S$20,"")="SI",Y27=""),"Código País",""),IF(AND(_xlfn.XLOOKUP($C$14,_Requeridos!$A$10:$A$20,_Requeridos!$T$10:$T$20,"")="SI",Z27=""),"Emplazamiento",""),IF(AND(_xlfn.XLOOKUP($C$14,_Requeridos!$A$10:$A$20,_Requeridos!$U$10:$U$20,"")="SI",AB27=""),"Centro de Costo",""),IF(AND(_xlfn.XLOOKUP($C$14,_Requeridos!$A$10:$A$20,_Requeridos!$V$10:$V$20,"")="SI",AC27=""),"Número de personal",""),IF(AND(_xlfn.XLOOKUP($C$14,_Requeridos!$A$10:$A$20,_Requeridos!$W$10:$W$20,"")="SI",AH27=""),"Valor Unitario","")),"✅ Completo"))
B28: 7 | G28: =IFERROR(_xlfn.XLOOKUP(F28,Clase!$C$2:$C$292,Clase!$B$2:$B$292,""),"") | AD28: =IFERROR(_xlfn.XLOOKUP(AB28,Ceco!$B$2:$B$901,Ceco!$C$2:$C$901,""),"") | AJ28: =IF(COUNTA(C28,D28,E28,F28,H28,I28,L28,M28,N28,P28,Q28,R28,S28,T28,U28,X28,Y28,Z28,AB28,AC28,AH28)=0,"",IF(LEN(_xlfn.TEXTJOIN(", ",TRUE,IF(AND(_xlfn.XLOOKUP($C$14,_Requeridos!$A$10:$A$20,_Requeridos!$B$10:$B$20,"")="SI",C28=""),"Orden de Inversión",""),IF(AND(_xlfn.XLOOKUP($C$14,_Requeridos!$A$10:$A$20,_Requeridos!$C$10:$C$20,"")="SI",D28=""),"Elemento PEP",""),IF(AND(_xlfn.XLOOKUP($C$14,_Requeridos!$A$10:$A$20,_Requeridos!$D$10:$D$20,"")="SI",E28=""),"Pedido",""),IF(AND(_xlfn.XLOOKUP($C$14,_Requeridos!$A$10:$A$20,_Requeridos!$E$10:$E$20,"")="SI",F28=""),"Descripción Activo SAP",""),IF(AND(_xlfn.XLOOKUP($C$14,_Requeridos!$A$10:$A$20,_Requeridos!$F$10:$F$20,"")="SI",G28=""),"Clase",""),IF(AND(_xlfn.XLOOKUP($C$14,_Requeridos!$A$10:$A$20,_Requeridos!$G$10:$G$20,"")="SI",H28=""),"Cantidad",""),IF(AND(_xlfn.XLOOKUP($C$14,_Requeridos!$A$10:$A$20,_Requeridos!$H$10:$H$20,"")="SI",I28=""),"Nombre principal AF",""),IF(AND(_xlfn.XLOOKUP($C$14,_Requeridos!$A$10:$A$20,_Requeridos!$I$10:$I$20,"")="SI",L28=""),"Fabricante",""),IF(AND(_xlfn.XLOOKUP($C$14,_Requeridos!$A$10:$A$20,_Requeridos!$J$10:$J$20,"")="SI",M28=""),"Nit Proveedor",""),IF(AND(_xlfn.XLOOKUP($C$14,_Requeridos!$A$10:$A$20,_Requeridos!$K$10:$K$20,"")="SI",N28=""),"Serie",""),IF(AND(_xlfn.XLOOKUP($C$14,_Requeridos!$A$10:$A$20,_Requeridos!$L$10:$L$20,"")="SI",P28=""),"Criterio Clas. 1",""),IF(AND(_xlfn.XLOOKUP($C$14,_Requeridos!$A$10:$A$20,_Requeridos!$M$10:$M$20,"")="SI",Q28=""),"Criterio Clas. 2",""),IF(AND(_xlfn.XLOOKUP($C$14,_Requeridos!$A$10:$A$20,_Requeridos!$N$10:$N$20,"")="SI",R28=""),"Criterio Clas. 3",""),IF(AND(_xlfn.XLOOKUP($C$14,_Requeridos!$A$10:$A$20,_Requeridos!$O$10:$O$20,"")="SI",S28=""),"Criterio Clas. 4",""),IF(AND(_xlfn.XLOOKUP($C$14,_Requeridos!$A$10:$A$20,_Requeridos!$P$10:$P$20,"")="SI",T28=""),"Criterio Clas. 5",""),IF(AND(_xlfn.XLOOKUP($C$14,_Requeridos!$A$10:$A$20,_Requeridos!$Q$10:$Q$20,"")="SI",U28=""),"Ubicación técnica",""),IF(AND(_xlfn.XLOOKUP($C$14,_Requeridos!$A$10:$A$20,_Requeridos!$R$10:$R$20,"")="SI",X28=""),"Centro",""),IF(AND(_xlfn.XLOOKUP($C$14,_Requeridos!$A$10:$A$20,_Requeridos!$S$10:$S$20,"")="SI",Y28=""),"Código País",""),IF(AND(_xlfn.XLOOKUP($C$14,_Requeridos!$A$10:$A$20,_Requeridos!$T$10:$T$20,"")="SI",Z28=""),"Emplazamiento",""),IF(AND(_xlfn.XLOOKUP($C$14,_Requeridos!$A$10:$A$20,_Requeridos!$U$10:$U$20,"")="SI",AB28=""),"Centro de Costo",""),IF(AND(_xlfn.XLOOKUP($C$14,_Requeridos!$A$10:$A$20,_Requeridos!$V$10:$V$20,"")="SI",AC28=""),"Número de personal",""),IF(AND(_xlfn.XLOOKUP($C$14,_Requeridos!$A$10:$A$20,_Requeridos!$W$10:$W$20,"")="SI",AH28=""),"Valor Unitario","")))>0,"⚠️ Faltan: "&_xlfn.TEXTJOIN(", ",TRUE,IF(AND(_xlfn.XLOOKUP($C$14,_Requeridos!$A$10:$A$20,_Requeridos!$B$10:$B$20,"")="SI",C28=""),"Orden de Inversión",""),IF(AND(_xlfn.XLOOKUP($C$14,_Requeridos!$A$10:$A$20,_Requeridos!$C$10:$C$20,"")="SI",D28=""),"Elemento PEP",""),IF(AND(_xlfn.XLOOKUP($C$14,_Requeridos!$A$10:$A$20,_Requeridos!$D$10:$D$20,"")="SI",E28=""),"Pedido",""),IF(AND(_xlfn.XLOOKUP($C$14,_Requeridos!$A$10:$A$20,_Requeridos!$E$10:$E$20,"")="SI",F28=""),"Descripción Activo SAP",""),IF(AND(_xlfn.XLOOKUP($C$14,_Requeridos!$A$10:$A$20,_Requeridos!$F$10:$F$20,"")="SI",G28=""),"Clase",""),IF(AND(_xlfn.XLOOKUP($C$14,_Requeridos!$A$10:$A$20,_Requeridos!$G$10:$G$20,"")="SI",H28=""),"Cantidad",""),IF(AND(_xlfn.XLOOKUP($C$14,_Requeridos!$A$10:$A$20,_Requeridos!$H$10:$H$20,"")="SI",I28=""),"Nombre principal AF",""),IF(AND(_xlfn.XLOOKUP($C$14,_Requeridos!$A$10:$A$20,_Requeridos!$I$10:$I$20,"")="SI",L28=""),"Fabricante",""),IF(AND(_xlfn.XLOOKUP($C$14,_Requeridos!$A$10:$A$20,_Requeridos!$J$10:$J$20,"")="SI",M28=""),"Nit Proveedor",""),IF(AND(_xlfn.XLOOKUP($C$14,_Requeridos!$A$10:$A$20,_Requeridos!$K$10:$K$20,"")="SI",N28=""),"Serie",""),IF(AND(_xlfn.XLOOKUP($C$14,_Requeridos!$A$10:$A$20,_Requeridos!$L$10:$L$20,"")="SI",P28=""),"Criterio Clas. 1",""),IF(AND(_xlfn.XLOOKUP($C$14,_Requeridos!$A$10:$A$20,_Requeridos!$M$10:$M$20,"")="SI",Q28=""),"Criterio Clas. 2",""),IF(AND(_xlfn.XLOOKUP($C$14,_Requeridos!$A$10:$A$20,_Requeridos!$N$10:$N$20,"")="SI",R28=""),"Criterio Clas. 3",""),IF(AND(_xlfn.XLOOKUP($C$14,_Requeridos!$A$10:$A$20,_Requeridos!$O$10:$O$20,"")="SI",S28=""),"Criterio Clas. 4",""),IF(AND(_xlfn.XLOOKUP($C$14,_Requeridos!$A$10:$A$20,_Requeridos!$P$10:$P$20,"")="SI",T28=""),"Criterio Clas. 5",""),IF(AND(_xlfn.XLOOKUP($C$14,_Requeridos!$A$10:$A$20,_Requeridos!$Q$10:$Q$20,"")="SI",U28=""),"Ubicación técnica",""),IF(AND(_xlfn.XLOOKUP($C$14,_Requeridos!$A$10:$A$20,_Requeridos!$R$10:$R$20,"")="SI",X28=""),"Centro",""),IF(AND(_xlfn.XLOOKUP($C$14,_Requeridos!$A$10:$A$20,_Requeridos!$S$10:$S$20,"")="SI",Y28=""),"Código País",""),IF(AND(_xlfn.XLOOKUP($C$14,_Requeridos!$A$10:$A$20,_Requeridos!$T$10:$T$20,"")="SI",Z28=""),"Emplazamiento",""),IF(AND(_xlfn.XLOOKUP($C$14,_Requeridos!$A$10:$A$20,_Requeridos!$U$10:$U$20,"")="SI",AB28=""),"Centro de Costo",""),IF(AND(_xlfn.XLOOKUP($C$14,_Requeridos!$A$10:$A$20,_Requeridos!$V$10:$V$20,"")="SI",AC28=""),"Número de personal",""),IF(AND(_xlfn.XLOOKUP($C$14,_Requeridos!$A$10:$A$20,_Requeridos!$W$10:$W$20,"")="SI",AH28=""),"Valor Unitario","")),"✅ Completo"))
